Workbook

Sheet Leeswijzer
A1: Database pakketadviezen Zorginstituut Nederland (ZIN) – geneesmiddelen
A2: Versie 1.0 · index-snapshot ZIN-website 09-09-2026 · opgebouwd met Claude · webcheck volledigheid t.o.v. ZIN-website 24-09-2026 (overzichtspagina 17-09-2026 + werkagenda 22-09-2026): 149/149 gepubliceerde sluisadviezen in index; 3 adviezen buiten de overzichtspagina toegevoegd (INT-160 t/m INT-162) · 24-09-2026: GVS-historie verwerkt (287 adviezen met basisgegevens, 2015–2026; 12 zonder pdf, 16 lopend); Intramuraal 163 volledig, 10 lopend, INT-172 zonder pdf.
A4: Doel
A5: Doel | B5: Alle pakketadviezen van ZIN over geneesmiddelen op één plek, gesplitst naar traject (GVS/extramuraal vs. intramuraal/sluis), met per dossier de kerngegevens én de argumenten die ZIN heeft gehanteerd, zodat die bij toekomstige dossiers als precedent kunnen worden ingezet.
A7: Opbouw van het bestand
A8: Intramuraal | B8: Register van sluisadviezen en overige adviezen over specialistische geneesmiddelen. Nu gevuld met de complete ZIN-index: 148 afgeronde adviezen (dec 2015 – aug 2026) plus 11 lopende beoordelingen. Eén rij per advies.
A9: GVS | B9: Register van GVS-adviezen (extramuraal). GVS-001 t/m GVS-016: lopende beoordelingen (werkagenda). GVS-101 e.v.: alle sinds 2015 gepubliceerde GVS-adviezen (productadviezen, bijlage 2-wijzigingen, klassebrede adviezen), toegevoegd op 24-09-2026 uit een inventaris van de ZIN-site via het Internet Archive; status 'Index' = nog niet inhoudelijk verwerkt.
A10: Argumenten | B10: De kern van de database: één rij per argument dat ZIN gebruikt, gecodeerd naar pakketcriterium en thema, met parafrase, positie t.o.v. de claim van de fabrikant, gewicht, precedentwaarde en bronverwijzing. Koppelt via Dossier-ID aan Intramuraal of GVS (geneesmiddel en datum worden automatisch opgehaald).
A11: Codeboek | B11: Keuzelijsten (bron van alle dropdowns) en definities. Pas de lijsten hier aan; de dropdowns volgen automatisch.
A12: Overzicht | B12: Tellingen per jaar/uitkomst, per pakketcriterium, extractievoortgang en therapeutisch gebied. Alles formules.
A14: Legenda kolomkleuren
A15: Grijze kop | B15: Automatisch overgenomen uit de ZIN-index. Kolommen met * zijn afgeleid uit de titel van het advies (stofnaam, merknaam, indicatie, gebied, uitkomst) – controleer ze bij gebruik.
A16: Gele kop | B16: Handmatig vullen uit het dossier (brief aan de minister, farmacotherapeutisch rapport, FE-rapport, BIA, ACP-verslag).
A17: Groene kop | B17: Formule – niet overschrijven.
A19: Invulvoorbeeld (verwacht formaat per handmatige kolom)
A20: Registratiehouder | B20: Bristol Myers Squibb
A21: Weesgeneesmiddel | B21: Ja / Nee (dropdown)
A22: Indicatiegroep (ziekte)* | B22: Folliculair lymfoom (dropdown; automatisch uit titel, controleren)
A23: Behandellijn* | B23: 3e lijn of later (dropdown; automatisch uit titel, controleren)
A24: Stand van wetenschap en praktijk (ZIN) | B24: Voldoet (dropdown)
A25: SW&P: kernreden oordeel (categorie) | B25: Indirecte vergelijking geaccepteerd (effect groot/consistent) (dropdown)
A26: SW&P: waarom positief/negatief (onderbouwing) | B26: Positief. Enkelarmige studie indirect vergeleken met ...; ZIN accepteerde dit omdat ...; GRADE zeer laag maar effect groot; voorwaarde: herbeoordeling na ... jaar.
A27: Therapeutische waarde t.o.v. comparator (ZIN) | B27: Meerwaarde (dropdown)
A28: Comparator (ZIN) | B28: docetaxel (tweedelijns NSCLC)
A29: Ziektelast (0–1) | B29: 0,85
A30: Referentiewaarde (€/QALY) | B30: 80.000 (dropdown)
A31: ICER fabrikant / ICER ZIN (€/QALY) | B31: 96.000 / 134.000 (alleen getallen)
... A39: Precedentwaarde | B39: Acceptatie van een NMA als basis voor meerwaarde bij ontbrekende directe vergelijking.
A41: Werkwijze om de database te vullen
A42: Stap 1 – Index actueel houden | B42: Nieuwe adviezen verschijnen op de ZIN-overzichtspagina van sluismiddelen (zie bronnen). Voeg een rij toe met ID, datum, titel en URL; kolom Jaar en het tabblad Overzicht lopen automatisch mee.
A43: Stap 2 – Basisgegevens | B43: Open de documentpagina (URL) en neem uit de brief aan de minister en het FE-rapport de gele kolommen over. Zet Status extractie op 'Basisgegevens'.
A44: Stap 3 – Argumenten | B44: Loop de brief, het farmacotherapeutisch rapport, het FE-rapport en het ACP-verslag door en leg elk relevant argument vast als aparte rij in tabblad Argumenten: criterium, thema, parafrase, positie, gewicht, precedentwaarde, bron + pagina. Zet Status extractie op 'Argumenten volledig'.
A45: Stap 4 – Controle | B45: Laat een collega steekproefsgewijs controleren en zet Status extractie op 'Gecontroleerd'.
A46: GVS-historie | B46: Zoek historische GVS-adviezen via de publicatiezoeker op zorginstituutnederland.nl (soort: Advies, trefwoord 'GVS-advies' of stofnaam) of via de Staatscourant-wijzigingen van de Regeling zorgverzekering; voeg ze als rij toe in tabblad GVS met nieuw ID (GVS-xxx).
A47: Zoeken naar precedenten | B47: Filter tabblad Argumenten op Thema (bijv. 'Indirecte vergelijking / NMA') en Positie ('Ondersteunt claim fabrikant') om snel alle dossiers te vinden waarin ZIN een vergelijkbare redenering heeft geaccepteerd; via Dossier-ID kom je bij de bron.
A49: Bronnen
A50: Index sluisadviezen (compleet, 2015–heden) | B50: https://www.zorginstituutnederland.nl/wat-wij-doen/programmas-en-samenwerkingsverbanden/horizonscan-geneesmiddelen/sluis-voor-dure-geneesmiddelen/overzicht-sluismiddelen-waarover-het-zorginstituut-heeft-geadviseerd
A51: Lopende pakketadviezen (sluis) | B51: https://www.zorginstituutnederland.nl/werkagenda/overzicht-pakketadviezen
A52: Lopende GVS-adviezen | B52: https://www.zorginstituutnederland.nl/werkagenda/overzicht-gvs-adviezen
A53: Licentie broninformatie | B53: De webcontent van ZIN is gepubliceerd onder CC0 1.0 (vermeld in de metadata van de overzichtspagina's); titels, data en URL's mogen vrij worden hergebruikt.
...

Sheet Intramuraal
A1: ID | B1: Status | C1: Datum advies | D1: Jaar | E1: Type advies* | F1: Geneesmiddel (uit titel)* | G1: Stofnaam (hoofd)* | H1: Merknaam* | I1: Indicatie (uit titel)* | J1: Therapeutisch gebied* | K1: Uitkomst advies | L1: Titel advies (ZIN) | M1: URL documentpagina ZIN | N1: Indicatiegroep (ziekte)* | O1: Behandellijn* | P1: Registratiehouder | Q1: Weesgeneesmiddel | R1: Datum sluisplaatsing | S1: Claim fabrikant | T1: Stand van wetenschap en praktijk (ZIN) | U1: SW&P: kernreden oordeel (categorie) | V1: SW&P: waarom positief/negatief (onderbouwing) | W1: Therapeutische waarde t.o.v. comparator (ZIN) | X1: Comparator (ZIN) | Y1: Ziektelast (0–1) | Z1: Referentiewaarde (€/QALY) | AA1: ICER fabrikant (€/QALY) | AB1: ICER ZIN basecase (€/QALY) | AC1: Kosteneffectief volgens ZIN | AD1: Geadviseerde prijsreductie (%) | AE1: Budgetimpact ZIN (€ mln/jaar) | AF1: Aantal patiënten/jaar (ZIN) | AG1: ACP-advies (kern) | AH1: Voorwaarden / gepast gebruik | AI1: Kernargumenten ZIN (samenvatting) | AJ1: Besluit minister / uitkomst onderhandeling | AK1: Datum opname basispakket | AL1: Status extractie | AM1: Opmerkingen
A2: INT-149 | B2: Lopend | D2: =IF(C2="","",YEAR(C2)) | E2: Initieel | F2: teprotumumab (Tepezza®) | G2: teprotumumab | H2: Tepezza | I2: de oogziekte van Graves | J2: Oogheelkunde | L2: Advies - wel of niet vergoeden teprotumumab (Tepezza®) voor de behandeling van de oogziekte van Graves | M2: https://www.zorginstituutnederland.nl/werkagenda/bloed-en-immuunsysteem/pakketadvies-sluisgeneesmiddel-teprotumumab-tepezza-voor-de-oogziekte-van-graves | N2: Niet-oncologisch (zie Indicatie) | O2: n.v.t. / onbekend | AL2: Index
A3: INT-150 | B3: Lopend | D3: =IF(C3="","",YEAR(C3)) | E3: Initieel | F3: amivantamab (Rybrevant®) in combinatie met chemotherapie | G3: amivantamab | H3: Rybrevant | I3: gevorderde niet-kleincellige longkanker | J3: Oncologie (solide tumoren) | L3: Advies - wel of niet vergoeden amivantamab (Rybrevant®) in combinatie met chemotherapie voor de behandeling van gevorderde niet-kleincellige longkanker | M3: https://www.zorginstituutnederland.nl/werkagenda/kanker/pakketadvies-sluisgeneesmiddel-amivantamab-rybrevant-in-combinatie-met-chemotherapie-voor-de-behandeling-van-gevorderde-niet-kleincellige-longkanker | N3: Solide tumor (zie Indicatie) | O3: n.v.t. / onbekend | AL3: Index
A4: INT-151 | B4: Lopend | D4: =IF(C4="","",YEAR(C4)) | E4: Initieel | F4: ciltacabtagene autoleucel (Carvykti®) | G4: ciltacabtagene autoleucel | H4: Carvykti | I4: multipel myeloom vanaf de tweede behandellijn | J4: Hemato-oncologie | L4: Advies - wel of niet vergoeden ciltacabtagene autoleucel (Carvykti®) voor de behandeling van multipel myeloom vanaf de tweede behandellijn | M4: https://www.zorginstituutnederland.nl/werkagenda/kanker/pakketadvies-sluisgeneesmiddel-ciltacabtagene-autoleucel-carvykti-bij-multipel-myeloom | N4: Multipel myeloom | O4: n.v.t. / onbekend | AL4: Index
A5: INT-152 | B5: Lopend | D5: =IF(C5="","",YEAR(C5)) | E5: Initieel | F5: durvalumab (Imfinzi®) | G5: durvalumab | H5: Imfinzi | I5: spierinvasieve blaaskanker | J5: Oncologie (solide tumoren) | L5: Advies - wel of niet vergoeden durvalumab (Imfinzi®) voor de behandeling van spierinvasieve blaaskanker | M5: https://www.zorginstituutnederland.nl/werkagenda/kanker/pakketadvies-sluisgeneesmiddel-durvalumab-imfinzi-bij-spierinvasieve-blaaskanker | N5: Solide tumor (zie Indicatie) | O5: n.v.t. / onbekend | AL5: Index
A6: INT-153 | B6: Afgerond advies | C6: 46279 | D6: =IF(C6="","",YEAR(C6)) -> 2026 | E6: Initieel | F6: inavolisib (Itovebi®) in combinatie met palbociclib en fulvestrant | G6: inavolisib | H6: Itovebi | I6: borstkanker | J6: Oncologie (solide tumoren) | K6: Alleen vergoeden na prijsdaling | L6: Advies - alleen vergoeden na prijsdaling inavolisib (Itovebi®) in combinatie met palbociclib en fulvestrant voor de behandeling van borstkanker | M6: https://www.zorginstituutnederland.nl/documenten/2026/09/14/pakketadvies-sluisgeneesmiddel-inavolisib-itovebi-in-combinatie-met-palbociclib-en-fulvestrant-voor-de-behandeling-van-borstkanker | N6: Borstkanker | O6: 1e lijn | P6: Roche | Q6: Nee | S6: Meerwaarde | T6: Voldoet | U6: Directe RCT met klinisch relevant effect | V6: Positief. Bewijs: RCT INAVO120 (inavolisib + palbociclib + fulvestrant vs. placebo + palbociclib + fulvestrant) bij PIK3CA-gemuteerde HR+/HER2- gevorderde borstkanker met recidief op/binnen 12 maanden na adjuvante endocriene therapie: klinisch relevante mediane OS-winst van 7 maanden; meer ernstige bijwerkingen en stakers; QoL ongepubliceerd maar volgens CSR-data niet negatief beïnvloed en achteruitgang mogelijk 11 maanden uitgesteld. CDK4/6-remmers zijn onderling gelijkwaardig (eerder ZIN-oordeel), dus één comparator volstaat; ctDNA- (studie) en weefseltest (NL) beide acceptabel. Studie representatief, al wordt in NL meer alpelisib in 2L gegeven → SWP, meerwaarde t.o.v. CDK4/6 + fulvestrant. | W6: Meerwaarde | X6: CDK4/6-remmer + fulvestrant (INAVO120: palbociclib + fulvestrant) | Y6: Hoog (referentiewaarde €80.000; relatief jonge groep, gem. 54 jaar; OS ~30 mnd, PIK3CA ~8 mnd korter) | Z6: 80000 | AA6: Basecase ZIN 613.940 | AB6: 613.940 (basecase ZIN; vervolgbehandelingen conform INAVO120 → 92% korting); scenario met vervolgbehandelingen naar NL-praktijk 575.638 (→ ~86%) | AC6: Nee | AD6: 89 (ZIN: midden tussen 92 en 86 na inspraak); ACP: ten minste 92 | AE6: 42,3 macrokosten (jaar 3); 39,2 na substitutie van CDK4/6 + fulvestrant; 37,8 incl. substitutie van alpelisib 2L; ca. 6,2 bij 89% korting | AF6: 163 in jaar 3; €330.035 per patiënt per behandeling, waarvan €289.248 inavolisib | AG6: ACP: basecase (92%) biedt de beste onderbouwing → niet opnemen tenzij ≥92% korting; weegt mee: aanzienlijke BI, dynamisch behandellandschap, verwachte indicatie-uitbreidingen, grote onzekerheid over uptake → kort financieel arrangement; geheime prijsafspraken voor (vervolg)behandelingen waar mogelijk meenemen; duidelijke gepast-gebruikafspraken met de beroepsgroep en bevordering van doelmatige inzet. | AH6: Korting 89% (ZIN) – ACP ≥92%; kort arrangement; PIK3CA-diagnostiek: CieBOD doet een uitspraak over de te gebruiken test (ZIN acht opname daarmee uitvoerbaar); gepast-gebruikafspraken; nettoprijzen van (vervolg)behandelingen meewegen. | AI6: INAVO120: OS +7 mnd → meerwaarde t.o.v. CDK4/6 + fulvestrant; QoL alleen via CSR. KE: ICER €613.940 (ZIN-basecase, INAVO120-vervolgbehandelingen) → 92%; NL-praktijkscenario €575.638 → 86%; ZIN kiest na inspraak het midden: 89% – de ACP houdt vast aan 92%. Utiliteit van één gezondheidstoestand zeer onzeker (kleine, geselecteerde groep). BI €39 mln op vraagprijs, €6 mln na korting. Hoogste kortingspercentage voor een RCT-onderbouwd middel in de database. | AJ6: Nog aanvullen (niet in dossier); index: alleen vergoeden na prijsdaling | AL6: Argumenten volledig | AM6: Bron: brief 14-09-2026 (5 p., gedateerd 8 september) + ACP-advies + FT-rapport + FE-rapport + BIA, gelezen via extract. Gepubliceerd na de index-snapshot; eerste PI3Kα-remmer in de sluis; ZIN en ACP verschillen expliciet van mening over het percentage (89 vs. 92).
A7: INT-154 | B7: Lopend | D7: =IF(C7="","",YEAR(C7)) | E7: Herbeoordeling | F7: osimertinib (Tagrisso®) | G7: osimertinib | H7: Tagrisso | I7: lokaal gevorderde niet-kleincellige longkanker | J7: Oncologie (solide tumoren) | L7: Advies - herbeoordeling kosteneffectiviteit osimertinib (Tagrisso®) voor de behandeling van lokaal gevorderde niet-kleincellige longkanker (herbeoordeling) | M7: https://www.zorginstituutnederland.nl/werkagenda/kanker/pakketadvies-sluisgeneesmiddel-osimertinib-tagrisso-bij-lokaal-gevorderde-niet-kleincellige-longkanker-herbeoordeling | N7: Solide tumor (zie Indicatie) | O7: n.v.t. / onbekend | AL7: Index
A8: INT-155 | B8: Lopend | D8: =IF(C8="","",YEAR(C8)) | E8: Initieel | F8: pirtobrutinib (Jaypirca®) | G8: pirtobrutinib | H8: Jaypirca | I8: een bepaalde vorm van bloedkanker | J8: Hemato-oncologie | L8: Advies - wel of niet vergoeden pirtobrutinib (Jaypirca®) voor de behandeling van een bepaalde vorm van bloedkanker | M8: https://www.zorginstituutnederland.nl/werkagenda/kanker/pakketadvies-sluisgeneesmiddel-pirobrutinib-jaypirca-bij-chronische-lymfatische-leukemie-cll | N8: Overig hematologisch | O8: n.v.t. / onbekend | AL8: Index
A9: INT-156 | B9: Lopend | D9: =IF(C9="","",YEAR(C9)) | E9: Initieel | F9: tafasitamab (Minjuvi®) | G9: tafasitamab | H9: Minjuvi | I9: recidiverend of refractair folliculair lymfoom | J9: Hemato-oncologie | L9: Advies - wel of niet vergoeden tafasitamab (Minjuvi®) voor de behandeling van recidiverend of refractair folliculair lymfoom | M9: https://www.zorginstituutnederland.nl/werkagenda/kanker/pakketadvies-sluisgeneesmiddel-tafasitamab-minjuvi-voor-de-behandeling-van-recidiverend-of-refractair-folliculair-lymfoom | N9: Folliculair lymfoom | O9: r/r (lijn niet gespecificeerd) | AL9: Index
A10: INT-157 | B10: Lopend | D10: =IF(C10="","",YEAR(C10)) | E10: Initieel | F10: trastuzumab-deruxtecan (Enhertu®) | G10: trastuzumab-deruxtecan | H10: Enhertu | I10: niet-kleincellige longkanker met HER2-mutatie | J10: Oncologie (solide tumoren) | L10: Advies - wel of niet vergoeden trastuzumab-deruxtecan (Enhertu®) voor de behandeling van niet-kleincellige longkanker met HER2-mutatie | M10: https://www.zorginstituutnederland.nl/werkagenda/kanker/pakketadvies-sluisgeneesmiddel-trastuzumab-deruxtecan-enhertu-voor-de-behandeling-van-niet-kleincellige-longkanker-met-her2-mutatie | N10: Solide tumor (zie Indicatie) | O10: n.v.t. / onbekend | AL10: Index
A11: INT-158 | B11: Lopend | D11: =IF(C11="","",YEAR(C11)) | E11: Initieel | F11: zanubrutinib (Brukinsa®) | G11: zanubrutinib | H11: Brukinsa | I11: lymfeklierkanker | J11: Hemato-oncologie | L11: Advies - wel of niet vergoeden zanubrutinib (Brukinsa®) voor de behandeling van lymfeklierkanker | M11: https://www.zorginstituutnederland.nl/werkagenda/kanker/pakketadvies-sluisgeneesmiddel-zanubrutinib-brukinsa-voor-de-behandeling-van-lymfeklierkanker | N11: Lymfoom (overig / onbepaald) | O11: n.v.t. / onbekend | AL11: Index
A12: INT-159 | B12: Lopend | D12: =IF(C12="","",YEAR(C12)) | E12: Initieel | F12: guselkumab (Tremfya®) | G12: guselkumab | H12: Tremfya | I12: plaque psoriasis | J12: Immunologie / IBD / dermatologie / reumatologie | L12: Advies - wel of niet vergoeden guselkumab (Tremfya®) voor de behandeling van plaque psoriasis | M12: https://www.zorginstituutnederland.nl/werkagenda/zintuigen-huid-en-haar/pakketadvies-sluisgeneesmiddel-guselkumab-tremfya-voor-de-behandeling-van-plaque-psoriasis | N12: Niet-oncologisch (zie Indicatie) | O12: n.v.t. / onbekend | AL12: Index
A13: INT-147 | B13: Afgerond advies | C13: 46260 | D13: =IF(C13="","",YEAR(C13)) -> 2026 | E13: Initieel | F13: lisocabtagene maraleucel (Breyanzi®) | G13: lisocabtagene maraleucel | H13: Breyanzi | I13: recidiverend of refractair folliculair lymfoom | J13: Hemato-oncologie | K13: Alleen vergoeden na prijsdaling | L13: Advies - alleen vergoeden na prijsdaling lisocabtagene maraleucel (Breyanzi®) voor de behandeling van recidiverend of refractair folliculair lymfoom | M13: https://www.zorginstituutnederland.nl/documenten/2026/08/26/pakketadvies-sluisgeneesmiddel-pakketadvies-sluisgeneesmiddel-lisocabtagene-maraleucel-breyanzi-voor-folliculair-lymfoom | N13: Folliculair lymfoom | O13: 3e lijn of later | P13: Bristol Myers Squibb | S13: Meerwaarde | T13: Voldoet | U13: Indirecte vergelijking geaccepteerd (effect groot/consistent) | V13: Positief. Bewijs: enkelarmige fase-2-studie TRANSCEND-FL, met een gepubliceerde indirecte vergelijking tegen een extern controlecohort (patiënten uit eerdere klinische studies én real-world-data behandeld met de standaardbehandeling; IPTW in de base case, propensity-matching als scenario). Geschatte overlevingskans op 30 maanden 88,9% vs. 76,9%; ondanks alle onzekerheden van de indirecte vergelijking lijkt liso-cel een klinisch relevant effect op de overleving te hebben. Bijwerkingen kunnen ernstig zijn maar zijn meestal goed te behandelen en lijken de kwaliteit van leven niet te beïnvloeden. WAR: indirecte vergelijking hier de enige haalbare methode; GRADE zeer laag maar OS-/PFS-curves lopen ver uiteen en de complete-responsrate is hoog; EPAR-data acceptabel; tisa-cel (nog in de sluis voor FL) geen comparator; discussie over 'passend onderzoek' (RCT was in beginsel mogelijk). Conclusie: SWP en meerwaarde t.o.v. de standaardbehandeling; door de korte follow-up onzekerheid over de lange termijn → herbeoordeling op termijn (WAR: zodra 8 jaar follow-up beschikbaar is). Contrast met axi-cel FL (INT-113, 2025): daar werd een vergelijkbare constructie verworpen wegens een niet-valide controlecohort (SCHOLAR-5, kortste OS) en te korte follow-up. | W13: Meerwaarde | X13: Gebruikelijke zorg vanaf 3e lijn (geïndividualiseerd, o.a. anti-CD20-combinaties/rechallenge), via indirecte vergelijking met extern controlecohort (IPTW; EPAR-data). Tisa-cel niet als comparator: zit nog in de sluis voor FL. | Y13: 0,45 (gemiddeld; uit het FE-model – beroepsgroep verwacht hogere ziektelast in de beoogde selecte groep, geen betrouwbare subgroepanalyse mogelijk) | Z13: 50000 | AA13: Basecase fabrikant door ZIN aangepast voor langetermijneffecten | AB13: 105.954 (na conservatieve aanpassingen langetermijneffecten; +ca. 5%-punt korting nodig bij nettoprijs lenalidomide −99%) | AC13: Nee | AD13: 66 (minstens 66% bij referentiewaarde €50.000; ZIN vindt méér dan 66% niet nodig gezien de strenge patiëntselectie door de CAR-T-tumorboard) | AE13: 8,8 macrokosten (jaar 3); 8,0 na substitutie (lijstprijzen) | AF13: 30 in jaar 3; €310.650 per toediening; €292.861 gemiddelde totale kosten per patiënt (incl. conditionering en overbrugging; niet iedereen die start krijgt liso-cel); ca. 700 nieuwe FL-diagnoses per jaar | AG13: Nu niet opnemen; alleen bij prijsdaling van minstens 66% (dan kosteneffectief bij €50.000/QALY). Weging: palliatieve patiënten met mogelijke levensverlenging, maar grote onzekerheid over studieresultaten; comparators mogelijk zelf niet kosteneffectief; liso-cel al vergoed voor andere indicaties met prijsafspraken en meer indicaties verwacht; snel bewegend behandellandschap → kort financieel arrangement. Waardering voor gepast-gebruikafspraken van de beroepsgroep. | AH13: Prijsdaling van (minstens) 66%; strenge patiëntselectie via de landelijke CAR-T-tumorboard en geprotocolleerde inzet (reden waarom ZIN geen hogere korting eist); bij de onderhandeling rekening houden met toekomstige concurrentie van andere CAR-T's bij FL; herbeoordeling op termijn wegens korte follow-up (WAR: 8 jaar); ACP: kort financieel arrangement. | AI13: SWP/meerwaarde via gepubliceerde indirecte vergelijking met extern cohort (30-maands OS 88,9% vs. 76,9%; WAR: enige haalbare methode, GRADE zeer laag maar curves lopen ver uiteen; herbeoordeling na 8 jaar). KEA na ZIN-aanpassingen van de langetermijneffecten (conservatieve, klinisch plausibele aannames; MCM/genezingsaanname en beslisboom verwijderd; utiliteiten uit alternatieve bronnen geaccepteerd) van voldoende kwaliteit: ICER €105.954/QALY bij referentiewaarde €50.000 (ziektelast 0,45 gemiddeld; selecte groep waarschijnlijk hoger, niet te analyseren) → minstens 66% korting; nettoprijs lenalidomide −99% verhoogt de korting met ~5%-punt (beperkt effect). ZIN eist bewust niet méér dan 66% vanwege vertrouwen in de tumorboard-selectie, maar wijst op toekomstige CAR-T-concurrentie. BI 30 patiënten, €8,0 mln. ACP: palliatieve groep met mogelijke levensverlenging maar grote onzekerheid; comparators mogelijk zelf niet kosteneffectief; indicatiestapeling → kort arrangement. | AJ13: Nog geen besluit bekend (stand 09-09-2026) | AL13: Argumenten volledig | AM13: Bron: brief 26-08-2026 + ACP-advies + FT-rapport + FE-rapport + BIA (bundel), aangevuld met WAR-verslagen (16-03 en 06-07-2026) uit batch 1. BMS-dossier. Sluisdatum niet in brief.
A14: INT-148 | B14: Afgerond advies | C14: 46260 | D14: =IF(C14="","",YEAR(C14)) -> 2026 | E14: Initieel | F14: belzutifan (Welireg®) | G14: belzutifan | H14: Welireg | I14: de ziekte van Von Hippel-Lindau | J14: Oncologie (solide tumoren) | K14: Alleen vergoeden na prijsdaling | L14: Advies - alleen vergoeden na prijsdaling belzutifan (Welireg®) voor de behandeling van de ziekte van Von Hippel-Lindau | M14: https://www.zorginstituutnederland.nl/documenten/2026/08/26/pakketadvies-sluisgeneesmiddel-belzutifan-welireg-voor-de-ziekte-van-von-hippel-lindau | N14: Overige solide tumoren | O14: Meerdere lijnen / indicatiebreed | P14: MSD | Q14: Ja | S14: Meerwaarde | T14: Voldoet | U14: Single-arm geaccepteerd (natuurlijk beloop als controle) | V14: Positief, met 'zeer onzekere' effectgrootte; retinaal Hb niet uitgesloten. Bewijs: enkelarmige LS-004 (n=61, primair RCC-VHL, allen ≥1 andere VHL-tumor; ~4 jaar gepubliceerde follow-up): RCC-tumoren krompen ≥30% of verdwenen bij twee derde; bij bijna de helft van de CZS-Hb en 90% van de pNET; slechts 6% CZS-Hb-progressie; effect houdt lang aan. Omdat spontane regressie zeer zelden voorkomt, is de krimp aan belzutifan toe te schrijven; de frequentie van lokale procedures lijkt rigoureus af te nemen (experts: zonder belzutifan onverminderd), maar de omvang van het relatieve effect is door het single-arm design zeer onzeker; een ongepubliceerde MAIC is niet meegenomen. Behandeldoel: uitstellen/voorkomen van lokale procedures (orgaanschade, symptomen), plausibel overlevingswinst. Directe QoL-data ontbreken – 'betreurenswaardig' bij deze aandoening. 'Niet geschikt voor lokale procedure' is subjectief en was geen inclusiecriterium → indicatiecommissie nadrukkelijk nodig. Retinaal Hb (niet aangevraagd bij EMA – onwenselijk) toch niet uitgesloten: hoge respons in kleine subgroep, tumortype-onafhankelijk mechanisme, unmet need; WAR-CG eens. Bijwerkingen bij bijna iedereen, goed behandelbaar → SWP, meerwaarde t.o.v. BSC. | W14: Meerwaarde | X14: Best ondersteunende zorg / actieve surveillance met lokale procedures (natuurlijk beloop; single-arm LS-004) | Y14: Hoog (referentiewaarde €80.000) | Z14: 80000 | AA14: 305903 | AB14: Range 305.903 (fabrikant-basecase, levenslang, ~5 jaar overlevingswinst – te optimistisch, ondergrens) tot 1.001.747 (conservatief scenario met ~6 jaar tijdshorizon en vrijwel geen overlevingswinst – niet realistisch, bovengrens); RCC-subgroep als meest betrouwbare analyse | AC14: Nee | AD14: Minstens 78 (midden van 73–82); ACP: dichter bij 73 (geen effectieve behandeling, kleine groep, beperkte BI) of bij 82 (grote onzekerheden, m.n. ontbrekende QoL-data) | AE14: 6,1 macrokosten (jaar 3); 9,0 in het hoogste scenario (58 patiënten) | AF14: 41 in jaar 3 (~450 VHL-patiënten in NL; ~41/jaar niet meer geschikt voor lokale procedure); 58 in hoog scenario; €160.892 per patiënt per jaar | AG14: ACP: op korte termijn beschikbaar (retinaal Hb niet uitgesloten), maar alleen voor een maatschappelijk aanvaardbare prijs: niet opnemen tenzij 73–82% korting. Richting 73%: aandoening zonder effectieve behandeling, kleine groep, beperkte BI; richting 82%: belangrijke onzekerheden, waarbij het gebrek aan QoL-data zwaar weegt. Verheugd dat de beroepsgroep kritische start-/stopcriteria, gepast gebruik, dosisreductie en 'drug holidays' oppakt; vertrouwen in een landelijke multidisciplinaire indicatiecommissie (behandeling in enkele expertisecentra). | AH14: Korting ≥78% (range 73–82); landelijke multidisciplinaire indicatiecommissie (noodzakelijk, m.n. voor retinaal Hb en de subjectieve 'niet geschikt voor lokale procedure'); start-/stopcriteria (voorstel beroepsgroep ligt er, MDO); monitoring van de inzet in de eerste jaren; onderzoek naar effectiviteit bij lagere dosering en drug holidays; gesprek met veldpartijen over gepast gebruik volgt. | AI14: Single-arm LS-004: tumorkrimp bij ⅔ (RCC), 90% (pNET), afname van lokale procedures – spontane regressie is zeldzaam → SWP/meerwaarde t.o.v. BSC, effectgrootte zeer onzeker; QoL niet gemeten ('betreurenswaardig'); retinaal Hb pragmatisch toegelaten ondanks ontbrekende EMA-registratie. KE: model adequaat maar parameters onvoldoende onderbouwd en model niet transparant; ZIN presenteert een range (fabrikant €305.903 als ondergrens; conservatief kortetermijnscenario €1.001.747 als bovengrens) en concludeert dat ook extra data de onzekerheid nauwelijks zullen verkleinen → 73–82%, advies ≥78%. BI €6,1–9,0 mln. Indicatiecommissie en dosisreductie-onderzoek als voorwaarden. | AJ14: Nog aanvullen (niet in dossier); index: alleen vergoeden na prijsdaling | AL14: Argumenten volledig | AM14: Bron: brief 26-08-2026 (6 p.) + ACP-advies (8 p.) + FT-rapport (96 p.) + FE-rapport + BIA, gelezen via extract. Eerste HIF-2α-remmer; enige advies met een expliciete kortingsrange (73–82%) én een middenwaarde als advies; ZIN laat een niet-geregistreerde subgroep (retinaal Hb) toe op mechanistische gronden.
A15: INT-146 | B15: Afgerond advies | C15: 46232 | D15: =IF(C15="","",YEAR(C15)) -> 2026 | E15: Indicatie-uitbreiding | F15: isatuximab (Sarclisa®) i.c.m. bortezomib, lenalidomide en dexamethason (IsaVRd) | G15: isatuximab | H15: Sarclisa | I15: multipel myeloom | J15: Hemato-oncologie | K15: Alleen vergoeden na prijsdaling | L15: Advies - vergoed isatuximab (Sarclisa®) i.c.m. bortezomib, lenalidomide en dexamethason (IsaVRd) voor de behandeling van multipel myeloom | M15: https://www.zorginstituutnederland.nl/documenten/2026/07/29/pakketadvies-sluisgeneesmiddel-isatuximab-sarclisa-i.c.m.-bortezomib-lenalidomide-en-dexamethason-isavrd-als-inductietherapie-voor-nieuw-gediagnosticeerd-multipel-myeloom-mm | N15: Multipel myeloom | O15: 1e lijn | P15: Sanofi | S15: Gelijke waarde | T15: Voldoet | U15: Niet-inferioriteit / gelijke waarde aangetoond | V15: Positief, als gelijke waarde t.o.v. DaraVRd (voorkeursinductie) en DaraVTd (gelijkwaardig alternatief). Geen directe vergelijking; ZIN maakte een naïeve indirecte vergelijking van drie open-label RCT's: GMMG-HD7 (IsaVRd vs. VRd), PERSEUS (DaraVRd vs. VRd) en CASSIOPEIA (DaraVTd vs. VTd). Effecten op OS en PFS t.o.v. de controlebehandelingen lijken vergelijkbaar; GMMG-HD7 en PERSEUS nog immatuur zonder OS-effect, CASSIOPEIA matuur met klinisch relevante OS-winst; PFS-puntschatter van IsaVRd exact op de PASKWIL-grens (HR 0,70), die van DaraVRd/DaraVTd eronder. ZIN verwacht dat door de vele effectieve vervolgbehandelingen in NDMM-TE geen OS-effect meer aantoonbaar zal zijn en dat het OS-effect van isatuximab en daratumumab in de praktijk gelijk is (zelfde werkingsmechanisme). Studieverschillen (DaraVRd/DaraVTd ook als consolidatie; onderhoud met daratumumab bij alle PERSEUS-patiënten) kunnen IsaVRd onderschatten resp. DaraVRd overschatten. Geen verschillen in QoL, ernstige bijwerkingen, stakers en gebruiksgemak (isatuximab 11 vs. daratumumab 14 toedieningen; subcutane vorm komt). Ondanks zeer immature data en relevante studieverschillen: geen klinisch relevante verschillen → gelijke waarde, mede gesteund door de eerdere vergelijkbare effectiviteit bij NDMM-TIE. | W15: Gelijke waarde | X15: DaraVRd (voorkeursinductie + consolidatie) en DaraVTd (gelijkwaardig alternatief); naïeve indirecte vergelijking GMMG-HD7 / PERSEUS / CASSIOPEIA via VRd/VTd | AC15: Niet beoordeeld | AD15: Nettoprijs niet hoger dan nettoprijs DaraVRd/DaraVTd voor deze indicatie; opname mag niet tot meerkosten leiden | AE15: 2,3 macrokosten (jaar 3); besparing van 2,0 door substitutie op lijstprijzen; met de door ZIN geadviseerde korting van 48,9% op daratumumab (advies DaraRd, januari 2025) nog €0,4 mln besparing | AF15: 47 in jaar 3; €49.391 per inductiebehandeling (DaraVRd €92.290 en DaraVTd €81.703 voor inductie + consolidatie) | AG15: Geen ACP-advies (gelijke waarde). | AH15: Opname mits nettoprijs ≤ nettoprijs DaraVRd/DaraVTd (geen meerkosten). ZIN wil met de beroepsgroep de overwegingen voor de keuze van inductiebehandeling omzetten in gepast-gebruikafspraken. | AI15: Gelijke waarde t.o.v. DaraVRd/DaraVTd via naïeve indirecte vergelijking van drie RCT's (PFS-HR IsaVRd 0,70 op de PASKWIL-grens; OS nog niet aantoonbaar door effectieve vervolglijnen; zelfde werkingsmechanisme; studieverschillen in consolidatie/onderhoud benoemd; gelijke QoL/veiligheid; minder toedieningen) → geen KEA; opname zonder meerkosten. BIA: 47 patiënten, inductie €49.391 vs. €81.703–92.290 → besparing €2,0 mln op lijstprijzen, €0,4 mln met de eerder geadviseerde 48,9% korting op daratumumab; subcutane isatuximab neutraliseert toedieningskostenverschil. | AJ15: Nog aanvullen (niet in dossier) | AL15: Argumenten volledig | AM15: Bron: brief 29-07-2026 + FT-rapport + BIA, gelezen via extract; geen FE, geen ACP/WAR-vermelding. Vervolg op eerder positief advies IsaVRd bij NDMM-TIE en Isa-Kd in het MM-pilotkader (INT-031).
A16: INT-145 | B16: Afgerond advies | C16: 46231 | D16: =IF(C16="","",YEAR(C16)) -> 2026 | E16: Indicatie-uitbreiding | F16: ipilimumab (Yervoy®) i.c.m. nivolumab (Opdivo®) | G16: ipilimumab | H16: Yervoy; Opdivo | I16: peritoneaal mesothelioom | J16: Oncologie (solide tumoren) | K16: Vergoeden | L16: Advies - vergoed ipilimumab (Yervoy®) i.c.m. nivolumab (Opdivo®) voor peritoneaal mesothelioom | M16: https://www.zorginstituutnederland.nl/documenten/2026/07/28/pakketadvies-sluisgeneesmiddel-ipilimumab-yervoy-in-combinatie-met-nivolumab-opdivo-bij-patienten-met-maligne-peritoneaal-mesothelioom | N16: Overige solide tumoren | O16: 1e lijn | P16: Bristol Myers Squibb | Q16: Nee | R16: Ipilimumab 'breed uitgesloten' in de sluis (alle toekomstige indicaties automatisch in de sluis); off-label indicatie op verzoek van de NVMO; formeel VWS-verzoek 25-06-2026 | S16: Meerwaarde | T16: Voldoet | U16: Richtlijn- en consensusgebaseerd (indicatiebrede aanpak / pilot) | V16: Positief, via een verkorte beoordeling van een off-label indicatie. Peritoneaal mesothelioom (~30 patiënten/jaar, 6% van de mesothelioom-gevallen; mediane OS 4–12 maanden) was uitgesloten van CheckMate-743 en zal wegens zeldzaamheid nooit in een RCT of registratie worden onderzocht. ZIN steunt op: (1) de richtlijn Mesothelioom (2022) die ipi + nivo als eerste keus adviseert onafhankelijk van histologie en PD-L1, en peritoneaal mesothelioom gezien de overeenkomsten gelijk behandelt ('data zijn er niet maar het lijkt logisch'); (2) de gangbare praktijk om chemotherapie voor peritoneaal te baseren op pleurale studies, met kleine ongecontroleerde studies die een vergelijkbaar effect suggereren; (3) het eigen advies uit 2021 (INT-042: meerwaarde niet-epitheloïd, gelijke waarde epitheloïd); (4) de SmPC die voorzichtig individueel gebruik bij peritoneaal mesothelioom noemt. Conclusie: SWP voor de gehele populatie, met dezelfde histologische tweedeling als bij pleuraal. | W16: Meerwaarde | X16: Pemetrexed + cis-/carboplatine (extrapolatie van pleuraal mesothelioom, INT-042); meerwaarde niet-epitheloïd, gelijke waarde epitheloïd | AC16: Niet beoordeeld | AD16: Geen nieuwe KEA: aansluiten bij de bestaande financiële afspraken voor ipilimumab + nivolumab bij pleuraal mesothelioom (gebaseerd op de KEA uit 2021) | AE16: 1,15 meerkosten (basecase, 13 patiënten) tot 1,33 (hoog scenario, 15 patiënten) na substitutie van pemetrexed/platina (€7.101 p.p.); macrokosten 1,24–1,43; werkelijk lager door bestaande afspraken | AF16: 13 (10 epitheloïd + 3 niet-epitheloïd) tot 15 per jaar bij 100% marktpenetratie; €95.446 per patiënt (€60.146 nivolumab + €35.300 ipilimumab), behandelduur ~1 jaar | AG16: Geen ACP-advies (verkorte beoordeling; geen nieuwe KEA). | AH16: Opname met gebruik van de bestaande prijsafspraken voor pleuraal mesothelioom; geen relevante gepast-gebruikrisico's verwacht; behandeling conform richtlijn Mesothelioom. | AI16: Eerste verkorte beoordeling van een off-label indicatie op verzoek van de beroepsgroep (NVMO) en VWS: zeldzaamheid (30/jaar) maakt RCT en registratie onhaalbaar; richtlijn, praktijk (chemo ook geëxtrapoleerd van pleuraal), eigen advies 2021 en SmPC dragen SWP. Geen nieuwe KEA 'gezien het lage kostenbeslag én de overlap in indicaties (beide asbestkanker)' → prijs volgt de bestaande pleurale afspraken. BI ~€1,2 mln (13–15 patiënten). Mechanisme 'breed uitgesloten' verklaart waarom een off-label indicatie überhaupt via de sluis loopt. | AJ16: Nog aanvullen (niet in dossier); index: vergoeden | AL16: Argumenten volledig | AM16: Bron: brief 28-07-2026 (4 p., ondertekend M.J. Janssen als voorzitter RvB), geen bijlagen (BIA in brief). BMS-dossier. Vervolg op INT-042 (pleuraal, 2021). Precedent voor off-label indicaties van 'breed uitgesloten' sluismiddelen: verkorte beoordeling, extrapolatie van SWP én van het bestaande arrangement.
A17: INT-144 | B17: Afgerond advies | C17: 46220 | D17: =IF(C17="","",YEAR(C17)) -> 2026 | E17: Indicatie-uitbreiding | F17: darolutamide (Nubeqa®) i.c.m. hormoontherapie (ADT) | G17: darolutamide | H17: Nubeqa | I17: uitgezaaide prostaatkanker | J17: Oncologie (solide tumoren) | K17: Niet vergoeden | L17: Advies - niet vergoeden darolutamide (Nubeqa®) i.c.m. hormoontherapie (ADT) voor de behandeling van uitgezaaide prostaatkanker | M17: https://www.zorginstituutnederland.nl/documenten/2026/07/17/pakketadvies-sluisgeneesmiddel-darolutamide-nubeqa-in-combinatie-met-hormoontherapie-adt-voor-de-behandeling-van-uitgezaaide-prostaatkanker | N17: Prostaatkanker | O17: 1e lijn | P17: Bayer | Q17: Nee | S17: Gelijke waarde | T17: Voldoet niet | U17: Effect te klein of niet klinisch relevant | V17: Negatief. Claim: gelijke waarde met apalutamide + ADT en enzalutamide + ADT; ZIN neemt ook abirateron (NVU-voorkeur op kosten) als comparator; de drie ARPI's gelden als gelijkwaardig, dus vergelijking met één volstaat. De registratiehouder deed – tegen het EMA-advies in – geen vergelijkende studie met een ARPI met OS als primair eindpunt. Een gepubliceerde NMA suggereert dat darolutamide + ADT mogelijk slechter werkt dan de andere ARPI's; de registratiestudies bevestigen dat: ARANOTE toont geen significant of klinisch relevant OS-effect vs. placebo, TITAN (apalutamide) wél, en dat is niet door de kortere studieduur te verklaren; PFS als surrogaat geeft dezelfde conclusie. Mogelijk minder ernstige bijwerkingen en stakers dan apalutamide (naïeve ITC, onzeker) zonder klinisch relevant QoL-voordeel. ZIN beoordeelt op data, niet op een verondersteld klasse-effect ('binnen een klasse kunnen klinisch relevante verschillen bestaan') → geen gelijke waarde → SWP niet voldaan (WAR). NVU wil een extra optie (interacties, heterogeniteit); NVMO, NFK en Prostaatkankerstichting achten de huidige opties toereikend. | W17: Niet te bepalen | X17: Apalutamide, enzalutamide en abirateron (+ ADT), als gelijkwaardige ARPI-klasse; vergelijking via placebo-RCT's (ARANOTE vs. TITAN) en NMA | AC17: Niet beoordeeld | AG17: Niet voorgelegd aan de ACP (advies stopt bij het SWP-criterium). | AH17: n.v.t. (negatief advies). | AI17: Gelijke-waarde-claim afgewezen op inhoud: ARANOTE toont geen OS-effect vs. placebo waar TITAN (apalutamide) dat wél doet; NMA wijst op mogelijk mindere werking; klasse-effect wordt expliciet niet aangenomen; fabrikant negeerde EMA-advies voor een head-to-head met OS → SWP niet voldaan → niet opnemen, geen KEA/BIA/ACP. Eerdere triplet-indicatie (INT-061) positief beoordeeld maar niet vergoed wegens mislukte onderhandeling. Verdeelde veldreacties (NVU vs. NVMO/NFK). | AJ17: Niet opgenomen (negatief advies) | AL17: Argumenten volledig | AM17: Bron: brief 17-07-2026 (4 p.) + FT-rapport (57 p.), gelezen via extract; geen BIA/FE/ACP. Tweede gelijke-waarde-claim die inhoudelijk strandt (na upadacitinib GCA, INT-123): hier omdat de eigen placebo-RCT geen OS-effect toont; expliciete afwijzing van het 'klasse-effect'-argument.
A18: INT-143 | B18: Afgerond advies | C18: 46219 | D18: =IF(C18="","",YEAR(C18)) -> 2026 | E18: Indicatie-uitbreiding | F18: durvalumab (Imfinzi®) | G18: durvalumab | H18: Imfinzi | I18: beperkt stadium kleincellige longkanker | J18: Oncologie (solide tumoren) | K18: Alleen vergoeden na prijsdaling | L18: Advies - vergoed durvalumab (Imfinzi®) voor de behandeling van beperkt stadium kleincellige longkanker | M18: https://www.zorginstituutnederland.nl/documenten/2026/07/16/pakketadvies-durvalumab-imfinzi-voor-de-behandeling-van-beperkt-stadium-kleincellige-longkanker | N18: Longkanker (NSCLC/SCLC) | O18: Onderhoud / consolidatie | P18: AstraZeneca | Q18: Nee | S18: Meerwaarde | T18: Voldoet | U18: Directe RCT met klinisch relevant effect | V18: Positief, beperkt tot WHO PS 0-1 na concurrente chemoradiotherapie (± PCI). Bewijs: dubbelblinde RCT ADRIATIC (durvalumab vs. placebo): geplande interimanalyse toont een klinisch relevant OS-effect, vooral door meer langdurig overlevenden – 8,9% meer in leven na 36 maanden, conform PASKWIL curatief (>5%), 'mogelijk klinisch relevant' (BI's van de overlevingspercentages overlappen; interim). Meer stakers en interventiegerelateerde bijwerkingen, geen QoL-verschil. Niet-fitte patiënten krijgen in NL sequentiële CRT en zaten niet in de studie → geen uitspraak → SWP alleen na concurrente CRT bij WHO 0-1. | W18: Meerwaarde | X18: Actief volgen na concurrente chemoradiotherapie ± PCI (ADRIATIC, placebogecontroleerde RCT) | Y18: Hoog (referentiewaarde €80.000) | Z18: 80000 | AA18: 79994 | AB18: 79.994 – precies op de referentiewaarde; onzeker omdat de finale OS-data ontbreken | AC18: Ja | AD18: Geen percentage; toch onderhandelen: indicatie-uitbreiding (ontwikkelkosten grotendeels terugverdiend → 'forse extra prijsverlaging maatschappelijk noodzakelijk', ACP PD-(L)1 2023), onzekerheid over duurzaamheid; publicatie finale OS voorwaardelijk voor vergoeding; tijdelijk arrangement | AE18: 17,5 macrokosten = BI (jaar 3; geen substitutie); mogelijk lager omdat alleen concurrente CRT-patiënten in aanmerking komen | AF18: 243 in jaar 3 (~1.500 SCLC-diagnoses in 2024); €72.150 per patiënt per behandeling | AG18: Geen apart ACP-document; ZIN verwijst naar het ACP-advies PD-(L)1-remmers (2023): bij indicatie-uitbreiding is een forse extra prijsverlaging maatschappelijk noodzakelijk omdat de ontwikkelkosten vaak al met de eerste indicatie(s) zijn terugverdiend. | AH18: Alleen WHO PS 0-1 na concurrente CRT (± PCI); publicatie van de finale OS-data als voorwaarde voor vergoeding; tijdelijk arrangement zodat de finale OS zo nodig kan worden herbeoordeeld; PD-(L)1-arrangementsbeleid; geen bewijs voor herbehandeling met immunotherapie bij progressie naar ES-SCLC – ZIN wil met de beroepsgroep bespreken wanneer dat te overwegen is. | AI18: ADRIATIC (interim): 36-maands OS +8,9% (PASKWIL curatief >5%), QoL gelijk → meerwaarde t.o.v. actief volgen, beperkt tot WHO 0-1 na concurrente CRT. KE: ICER €79.994 – precies op de grens – kosteneffectief maar onzeker door ontbrekende finale OS. Toch onderhandelen op drie gronden: indicatie-uitbreiding (terugverdiend), PD-(L)1-klassebeleid, en onzekerheid over duurzaamheid → publicatie finale OS als vergoedingsvoorwaarde + tijdelijk arrangement. BI €17,5 mln (243 patiënten). Herbehandeling met I-O na progressie als open gepast-gebruikvraag. | AJ18: Nog aanvullen (niet in dossier); index: vergoeden (na onderhandeling) | AL18: Argumenten volledig | AM18: Bron: brief 16-07-2026 (5 p.) + FT-rapport + FE-rapport + BIA, gelezen via extract; geen ACP-document. Vierde durvalumab-dossier (INT-014 PACIFIC 2019, INT-134, INT-139). Eerste dossier waarin publicatie van finale OS-data expliciet een vergoedingsvoorwaarde is.
A19: INT-142 | B19: Afgerond advies | C19: 46217 | D19: =IF(C19="","",YEAR(C19)) -> 2026 | E19: Initieel | F19: acalabrutinib (Calquence®) | G19: acalabrutinib | H19: Calquence | I19: lymfeklierkanker | J19: Hemato-oncologie | K19: Alleen vergoeden na prijsdaling | L19: Advies - alleen vergoeden na prijsdaling acalabrutinib (Calquence®) voor de behandeling van lymfeklierkanker | M19: https://www.zorginstituutnederland.nl/documenten/2026/07/14/pakketadvies-sluisgeneesmiddel-acalabrutinib-calquence-voor-mantelcellymfoom | N19: Mantelcellymfoom | O19: 2e lijn | P19: AstraZeneca | Q19: Nee | S19: Gelijke waarde | T19: Voldoet | U19: Niet-inferioriteit / gelijke waarde aangetoond | V19: Positief, conform de claim van gelijke waarde t.o.v. ibrutinib. Bewijs: acalabrutinib alleen in een enkelarmige fase-2-studie; ibrutinib in één RCT en enkele single-arm studies; geen directe vergelijking, dus indirecte vergelijking incl. twee gepubliceerde MAIC's: op overleving, uitstel van ziekte en tumorrespons waarschijnlijk ten minste vergelijkbare resultaten; geen klinisch relevante verschillen in ernstige bijwerkingen en stakers. Onzekerheid door onbekende variabelen en populatieverschillen (ibrutinib-studies meer hoogrisicopatiënten → mogelijke bias vóór acalabrutinib), waarvoor de MAIC's corrigeerden met een vergelijkbaar OS-effect. Ondersteunend: vergelijkbaar werkingsmechanisme en eerdere gelijke-waardeconclusies voor beide middelen bij andere indicaties (CLL). Conclusie: voldoende aannemelijk dat acalabrutinib ten minste gelijke waarde heeft → SWP voldaan. | W19: Gelijke waarde | X19: Ibrutinib (eerste keus bij recidief na chemo-immunotherapie; indirecte vergelijking met twee gepubliceerde MAIC's) | AC19: Niet beoordeeld | AD19: Nettoprijs per behandeling niet hoger dan nettoprijs per behandeling met ibrutinib | AE19: 7,4 macrokosten (jaar 3); mogelijke besparing 3,8 na substitutie van ibrutinib (lijstprijzen; werkelijke besparing onbekend) | AF19: 192 in jaar 3; €55.037 per patiënt per jaar; gemiddelde behandelduur 25,3 maanden voor beide middelen | AG19: Geen ACP-advies (gelijke waarde; geen WAR-toets van KE). | AH19: Opname pas als de nettoprijs per behandeling niet hoger is dan die van ibrutinib. | AI19: Gelijke waarde t.o.v. ibrutinib via indirecte vergelijking en twee MAIC's (correctie voor hoger-risico populatie in ibrutinib-studies), gesteund door zelfde werkingsmechanisme en eerdere CLL-conclusies → geen KEA. BIA: 192 patiënten, €55.037 p.p./jaar, behandelduur 25,3 maanden voor beide middelen (groot verschil in follow-up registratiestudies: 38,2 vs. 16 maanden), beroepsgroep akkoord; besparing €3,8 mln op lijstprijzen, werkelijke besparing onbekend. Advies: nettoprijs per behandeling ≤ ibrutinib. Minister bereikte akkoord; vergoed per 29-08-2026. | AJ19: Akkoord met leverancier; vergoed per 29-08-2026 (Stcrt. 2026-30698) | AK19: 46263 | AL19: Argumenten volledig | AM19: Bron: brief 14-07-2026 + FT-rapport + BIA, gelezen via extract; geen FE, geen ACP. Besluit: akkoord met leverancier, vergoed per 29-08-2026 (Stcrt. 2026-30698). Zusterdossiers INT-043 (CLL 2022), INT-046/INT-062 (zanubrutinib).
A20: INT-141 | B20: Afgerond advies | C20: 46212 | D20: =IF(C20="","",YEAR(C20)) -> 2026 | E20: Initieel | F20: amivantamab (Rybrevant®) in combinatie met lazertinib (Lazcluze®) | G20: amivantamab | H20: Rybrevant; Lazcluze | I20: gevorderde niet-kleincellige longkanker | J20: Oncologie (solide tumoren) | K20: Alleen vergoeden na prijsdaling | L20: Advies - alleen vergoeden na prijsdaling amivantamab (Rybrevant®) in combinatie met lazertinib (Lazcluze®) voor de behandeling van gevorderde niet-kleincellige longkanker | M20: https://www.zorginstituutnederland.nl/documenten/2026/07/09/pakketadvies-amivantamab-rybrevant-icm-lazertinib-lazcluze-voor-gevorderde-niet-kleincellige-longkanker | N20: Longkanker (NSCLC/SCLC) | O20: 1e lijn | P20: Janssen | Q20: Nee | S20: Meerwaarde | T20: Voldoet | U20: Niet-inferioriteit / gelijke waarde aangetoond | V20: Positief, als gelijke waarde t.o.v. osimertinib + chemotherapie – de door ZIN (april 2026) tot nieuwe eerste keus verklaarde combinatie die zelf nog niet wordt vergoed (onderhandeling loopt). De claim (meerwaarde t.o.v. osimertinib-monotherapie) is daarmee achterhaald; de beroepsgroep ziet dezelfde plek voor beide combinaties. Bewijs: MARIPOSA (ami + laz vs. osimertinib) en FLAURA2 (osi + chemo vs. osimertinib), geen directe vergelijking: geen klinisch relevante verschillen in overleving en QoL tussen de combinaties; beide meer toxiciteit dan osimertinib-mono, met verschillend type bijwerkingen; amivantamab s.c. of i.v. mogelijk, chemo alleen i.v.; keuze op individuele kenmerken en voorkeuren → SWP, gelijke waarde. | W20: Gelijke waarde | X20: Osimertinib + chemotherapie (nieuwe standaard sinds INT-132; indirecte vergelijking MARIPOSA vs. FLAURA2 via osimertinib-mono) | AC20: Niet beoordeeld | AD20: Netto behandelkosten niet hoger dan netto behandelkosten osimertinib + chemotherapie (waarvoor de onderhandeling nog loopt) | AE20: Scenario 1 (alleen ami + laz beschikbaar): 74,4 macro / 38,9 meerkosten na substitutie van osimertinib-mono; scenario 2 (beide combinaties): 37,2 macro / 16,0 meerkosten na substitutie van osi + chemo (jaar 3, lijstprijzen) | AF20: 743 (scenario 1) of 371 (scenario 2) in jaar 3; €283.133 per patiënt over 3 jaar (€145.067 amivantamab + €138.066 lazertinib) | AG20: Geen ACP-advies (gelijke waarde). | AH20: Netto behandelkosten ≤ osimertinib + chemotherapie; onzekerheid over behandelduur en marktverdeling; prijsafspraken voor osimertinib-mono bestaan al en voor beide combinaties volgen nog. | AI20: Het anker verschuift tijdens het traject: door het osimertinib + chemo-advies (april 2026) is de meerwaarde-claim t.o.v. osimertinib-mono irrelevant en wordt ami + laz via indirecte vergelijking gelijkwaardig aan osi + chemo → geen KEA, nettokosten ≤ osi + chemo (nog niet vergoed, onderhandeling loopt). BIA in twee scenario's (743 vs. 371 patiënten; €38,9 vs. €16,0 mln). Toedieningsvorm (s.c. amivantamab) en bijwerkingenprofiel bepalen de keuze in de spreekkamer, niet het waardeoordeel. | AJ20: Nog aanvullen (niet in dossier); index: alleen vergoeden na prijsdaling | AL20: Argumenten volledig | AM20: Bron: brief 09-07-2026 (4 p.) + FT-rapport + BIA, gelezen via extract; geen FE, geen ACP. Eerste dossier waarin een nog-niet-vergoede combinatie (in onderhandeling) als prijsanker dient; amivantamab + chemo (exon 20) in aparte beoordeling (INT-150).
A21: INT-140 | B21: Afgerond advies | C21: 46203 | D21: =IF(C21="","",YEAR(C21)) -> 2026 | E21: Initieel | F21: belantamab mafodotin (Blenrep®) in combinatie met bortezomib en dexamethason | G21: belantamab mafodotin | H21: Blenrep | I21: multipel myeloom | J21: Hemato-oncologie | K21: Alleen vergoeden na prijsdaling | L21: Advies - alleen vergoeden na prijsdaling belantamab mafodotin (Blenrep®) in combinatie met bortezomib en dexamethason voor de behandeling van multipel myeloom | M21: https://www.zorginstituutnederland.nl/documenten/2026/06/30/pakketadvies-sluisgeneesmiddel-belantamab-mafodotin-blenrep-voor-de-behandeling-van-multipel-myeloom | N21: Multipel myeloom | O21: 2e lijn | P21: GSK | S21: Meerwaarde | T21: Voldoet | U21: Directe RCT met klinisch relevant effect | V21: Positief. Bewijs: RCT DREAMM-7 (BVd vs. DVd) bij r/r MM na ≥1 lijn; 39 maanden follow-up is bij deze relatief lange overleving te kort voor een mediaan-OS-verschil, maar bij de datacut van 07-10-2024 was 28% (BVd) vs. 41% (DVd) overleden. ZIN acht het daarom acceptabel naar het surrogaat PFS te kijken: mediane PFS 36,6 vs. 13,4 maanden (+23,2 maanden; HR 0,41), wat het vertrouwen in een klinisch relevant OS-effect versterkt; een NMA toont een vergelijkbaar effect t.o.v. de vier andere standaardcombinaties. DREAMM-7 includeerde alleen daratumumab-niet-refractaire patiënten; de beroepsgroep wil ook daratumumab-refractaire patiënten behandelen en ZIN verwacht op basis van het verschillende werkingsmechanisme geen invloed op het effect. QoL gelijk aan DVd. Ongunstiger bijwerkingenprofiel (oogtoxiciteit, trombocytopenie; klinisch relevant meer stakers), maar grotendeels reversibel en beheersbaar met monitoring en dosisaanpassing, zonder QoL-verschil. Het overlevingseffect is zo groot dat meerwaarde t.o.v. behandeling naar keuze van de arts wordt geconcludeerd. | W21: Meerwaarde | X21: Behandeling naar keuze van de arts (vijf combinaties); DREAMM-7 direct vs. DVd, NMA voor de overige vier | Z21: 80000 | AA21: 184047 | AB21: 210.862 (met eerder door ZIN geadviseerde kortingen op de comparators toegepast) | AC21: Nee | AD21: Ten minste 61 (t.o.v. bij benadering kosteneffectieve comparators); 49 op lijstprijzen | AE21: 95,3 macrokosten (jaar 3); 70,4 na substitutie (gerectificeerd 30-06-2026 wegens uitstroomcorrectie); ACP: >€120 mln verwacht | AF21: 554 in jaar 3; kosten per patiënt €201.964 (jaar 1), €165.404 (jaar 2), €94.336 (jaar 3) | AG21: ACP: niet opnemen tenzij ≥61% prijsdaling. Weegt zwaar: effectiviteit gebaseerd op immature data met veel onzekerheid over de lange termijn; vergelijking met niet-doelmatige zorg; verwachte budgetimpact >€120 mln; zicht op concurrerende middelen en mogelijke indicatie-uitbreiding → kort financieel arrangement en herbeoordeling zodra OS-data beschikbaar zijn; MM-uitgaven al zeer hoog → maatschappelijk belang van een hogere korting. | AH21: Prijsdaling ≥61%; arrangement met herbeoordeling bij finale(re) OS-data; kort arrangement; doelmatigheidsonderzoek (dosisverlaging met behoud van werkzaamheid lijkt mogelijk); gepast-gebruikmaatregelen van de beroepsgroep tegen oogtoxiciteit en voor juiste inzet bij ouderen. | AI21: DREAMM-7 (RCT vs. DVd): PFS +23,2 mnd (HR 0,41), OS immatuur maar 28% vs. 41% overleden → meerwaarde ondanks oogtoxiciteit; extrapolatie naar dara-refractaire patiënten plausibel (ander werkingsmechanisme). KEA voldoende: ICER €184.047 op lijstprijzen (−49%), maar met de door ZIN eerder geadviseerde kortingen op de comparators €210.862 → ≥61% korting om kosteneffectief te zijn t.o.v. 'bij benadering kosteneffectieve' comparators. Onzekerheden: OS-extrapolatie op interim-data, aanhoudend effect na stoppen zonder scenario (niet geleverd), effect bij dara-refractaire patiënten aangenomen gelijk – acceptabel gezien het grote overlevingsvoordeel; herbeoordeling sterk aanbevolen. BI: 554 patiënten, €70,4 mln (na rectificatie); CAR-T (zelfde BCMA-target) zal inzet verminderen, sequentie onduidelijk; toxiciteit kan tot dosisverlaging leiden. Hoge MM-uitgaven → hogere korting maatschappelijk gewenst. | AJ21: Nog aanvullen (niet in dossier) | AL21: Argumenten volledig | AM21: Bron: gerectificeerde brief 30-06-2026 (oorspronkelijk 13-05-2026; behandelkosten binnen de BIA-horizon gecorrigeerd voor uitstroom) + ACP-advies + FT + FE + BIA, gelezen via extract. Eerste dossier waarin ZIN de ICER standaard herberekent met eerder geadviseerde comparatorkortingen (49% → 61%).
A22: INT-137 | B22: Afgerond advies | C22: 46169 | D22: =IF(C22="","",YEAR(C22)) -> 2026 | E22: Herbeoordeling | F22: brexucabtagene autoleucel (Tecartus®) | G22: brexucabtagene autoleucel | H22: Tecartus | I22: acute lymfatische leukemie (ALL) | J22: Hemato-oncologie | K22: Alleen vergoeden na prijsdaling | L22: Advies - alleen vergoeden na prijsdaling brexucabtagene autoleucel (Tecartus®) voor de behandeling van acute lymfatische leukemie (ALL) (herbeoordeling) | M22: https://www.zorginstituutnederland.nl/documenten/2026/05/27/pakketadvies-sluisgeneesmiddel-brexucabtagene-autoleucel-tecartus-voor-de-behandeling-van-acute-lymfatische-leukemie-all | N22: B-ALL | O22: r/r (lijn niet gespecificeerd) | P22: Kite / Gilead | Q22: Ja | R22: Sluis; eerder advies 15-01-2025 (INT-096: niet opnemen wegens onbruikbare KEA); herindiening KEA | S22: Meerwaarde | T22: Voldoet | U22: Indirecte vergelijking geaccepteerd (effect groot/consistent) | V22: Positief, bevestiging van 2025 (INT-096). ZUMA-3 (single-arm) indirect vergeleken met SCHOLAR-3: OS-verlenging 19,2 maanden, klinisch relevante QoL-verbetering na 3 maanden; onzekerheden door indirecte vergelijking, lage aantallen en verschillen met de Nederlandse praktijk. Nieuwe data met 45 maanden follow-up: 38,6% in leven na 54 maanden, wat het langetermijneffect bevestigt en het SWP-oordeel (getrokken op 21 maanden follow-up) onderschrijft. Voldoende vertrouwen in klinisch relevante overlevingswinst zonder verlies van kwaliteit van leven. | W22: Meerwaarde | X22: Blinatumomab, inotuzumab ozogamicine of chemotherapie (± alloSCT); extern cohort SCHOLAR-3 | Z22: 80000 | AA22: Basecase herindiening; door ZIN aangepast op de genezingsaanname | AB22: 126029 | AC22: Nee | AD22: Meer dan 44 (minstens 44% om kosteneffectief te zijn; meer wegens onzekerheid en ondoelmatige comparator) | AE22: 6,4 macrokosten (jaar 3); 4,6 na substitutie (BIA 2025 ongewijzigd); in werkelijkheid hoger door verzekeraarsafspraken over blinatumomab/inotuzumab | AF22: 23 in jaar 3 (beroepsgroep verwacht mogelijk minder door nieuwe eerstelijnsopties); €360.000 per toediening; €277.818 per patiënt per jaar | AG22: ACP: beschikbaarheid belangrijk, maar alleen tegen een maatschappelijk aanvaardbare prijs; niet opnemen tenzij ≥44% prijsdaling (ICER onder €80.000). Weegt mee: ernstig zieke maar zeer kleine groep, beperkte budgetimpact en klinisch relevant langere overleving voor een aanzienlijk deel van de patiënten. Daartegenover: de comparators zijn hoogstwaarschijnlijk ondoelmatig, zodat 44% de ondoelmatigheid in stand houdt – de ACP mist instrumenten voor betere prijsadvisering. Dynamisch landschap → kort financieel arrangement. Waardering voor de verantwoordelijkheid van de beroepsgroep bij patiëntselectie en gepast gebruik. | AH22: Prijsdaling >44%; kort financieel arrangement; landelijke CAR-T-tumorboard en geprotocolleerde inzet. | AI22: SWP/meerwaarde bevestigd met 45 maanden follow-up (38,6% in leven na 54 mnd). Herindiening KEA met langere follow-up en op verzoek gewijzigde aannames; ZIN paste de genezingsaanname aan, waarna de analyse bruikbaar was: ICER €126.029/QALY → minstens 44% korting; ZIN adviseert méér dan 44% wegens (kosten)effectiviteitsonzekerheid en de onbekende doelmatigheid van de standaardbehandeling. BIA 2025 gehandhaafd (23 patiënten, €4,6 mln netto). ACP: ≥44%, kort arrangement, erkent dat 44% ondoelmatigheid in stand houdt. | AJ22: Nog aanvullen (niet in dossier) | AL22: Argumenten volledig | AM22: Bron: gebundelde PDF (brief 27-05-2026; ACP-advies; FT-rapport; herbeoordeling FE-rapport; BIA), gelezen via extract. Vervolg op INT-096. Brexu-cel voor MCL wordt niet vergoed omdat prijsonderhandelingen mislukten (vermeld in brief).
A23: INT-138 | B23: Afgerond advies | C23: 46169 | D23: =IF(C23="","",YEAR(C23)) -> 2026 | E23: Herbeoordeling | F23: ciltacabtagene autoleucel (Carvykti®) | G23: ciltacabtagene autoleucel | H23: Carvykti | I23: multipel myeloom | J23: Hemato-oncologie | K23: Alleen vergoeden na prijsdaling | L23: Advies - alleen vergoeden na prijsdaling ciltacabtagene autoleucel (Carvykti®) voor de behandeling van multipel myeloom (herbeoordeling) | M23: https://www.zorginstituutnederland.nl/documenten/2026/05/27/pakketadvies-sluisgeneesmiddel-cilta-cel-carvykti-bij-multipel-myeloom-herbeoordeling | N23: Multipel myeloom | O23: 3e lijn of later | P23: Janssen | Q23: Ja | R23: Sluis; adviezen 20-10-2022 (INT-052, KEA onbruikbaar) en 18-02-2025 (INT-099, ≥35%); onderhandeling mislukt → november 2025 niet opgenomen; herbeoordeling FE op verzoek fabrikant (dec. 2025) met steun HOVON, NVvH en Hematon | S23: Meerwaarde | T23: Voldoet | U23: Indirecte vergelijking geaccepteerd (effect groot/consistent) | V23: Ongewijzigd (SWP en meerwaarde t.o.v. de standaardbehandeling vanaf de vierde lijn, zie INT-099). De update betreft de KE op basis van bijna tweemaal zo lange follow-up van de registratiestudie (61,3 vs. 34,5 maanden), verwerkt in het FE-model met klinische validatie van de langetermijnschattingen voor (progressievrije) overleving. Onzeker blijft het effect op post-progressie-overleving (beroepsgroep: klinisch aannemelijk maar grootte onzeker; sterk afhankelijk van vervolgbehandelingen) en de kosten/effecten van vervolgbehandeling in een veranderend landschap. | W23: Meerwaarde | X23: Standaardbehandeling 4L+ (indirecte vergelijking; zie INT-099) | Z23: 80000 | AB23: 71.267 op lijstprijzen (geüpdatete en aangepaste FE-analyse); scenario's blijven onder 80.000; kosteneffectief maar afhankelijk van nettoprijzen van standaard- en vervolgbehandelingen → ~5% korting | AC23: Ja | AD23: Meer dan 5 (5 volgens KEA, afhankelijk van nettoprijzen van comparator/vervolgbehandelingen; méér wegens resterende onzekerheid en zeer hoge BI) | AE23: 37,9–46,2 (jaar 3, op vraagprijs); stijgt verder bij de 2L-indicatie (beoordeling start 2026, INT-151) | AF23: Zie BIA (4L+; ~1.400 MM-diagnoses/jaar) | AG23: Geen nieuw ACP-advies (update FE; WAR). | AH23: Korting >5%; rekening houden met de onderhandelde nettoprijzen van standaard- en vervolgbehandelingen; onzekerheid over post-progressie-overleving en vervolgbehandelingen; komende 2L-indicatie. | AI23: Langere follow-up (61 mnd) verandert het beeld radicaal: van ≥35% (2025) naar ~5% (ICER €71.267, kosteneffectief bij €80.000). ZIN accepteert nu de langetermijn-PFS/OS-extrapolaties na klinische validatie, houdt onzekerheid over post-progressie-overleving en vervolgbehandelingen, en vraagt 'meer dan 5%' vanwege die onzekerheid en een BI van €38–46 mln (plus komende 2L-uitbreiding). Derde geval (na Libmeldy, sacituzumab) waarin follow-updata een mislukte onderhandeling heropenen en de kortingseis fors verlagen. | AJ23: Heronderhandeling geadviseerd; index: alleen vergoeden na prijsdaling | AL23: Argumenten volledig | AM23: Bron: brief 27-05-2026 (4 p.) + FE-herbeoordelingsrapport (19-05-2026) + FT + BIA, gelezen via extract (EPAR-bijlage niet meegenomen). Vervolg op INT-052 en INT-099. Grootste kortingsdaling in de database door langetermijndata (35% → 5%).
